Workbook
Name active: Assumptions!$I$25:$I$30
Name AddressOfCells: _xlfn.LAMBDA(_xlpm.Array,_xlfn.MAP(_xlpm.Array,_xlfn.LAMBDA(_xlpm.a,ADDRESS(ROW(_xlpm.a),COLUMN(_xlpm.a),4))))
Name Alphabet: _xlfn.LAMBDA(CHAR(_xlfn.SEQUENCE(26,,65)))
Name AlphaShift: _xlfn.LAMBDA(_xlpm.startcode,_xlpm.adjustment,_xlpm.startingletter,MOD(_xlpm.startcode+_xlpm.adjustment-_xlpm.startingletter,26)+_xlpm.startingletter)
Name Arrows: _xlfn.LAMBDA(_xlop.ShowHV,IF(_xlpm.ShowHV,{"↓",1,0;"↑",-1,0;"→",0,1;"←",0,-1;"↘",1,1;"↖",-1,-1;"↙",1,-1;"↗",-1,1},{"↓";"↑";"→";"←";"↘";"↖";"↙";"↗"}))
Name BoardGameMove: _xlfn.LAMBDA(_xlpm.MoveValue,_xlpm.EndSpace,MOD(_xlpm.MoveValue-1,_xlpm.EndSpace)+1)
Name cust: Assumptions!$B$25:$B$30
Name DiceNumExtract: _xlfn.LAMBDA(_xlpm.Dice,_xlfn.UNICODE(_xlpm.Dice)-9855)
Name Exists: _xlfn.LAMBDA(_xlpm.Item,_xlpm.List,_xlop.SearchMode,ISNUMBER(IF(_xlpm.SearchMode,_xleta.SEARCH,_xleta.XMATCH)(_xlpm.Item,_xlpm.List)))
Name ib_rate: Assumptions!$H$25:$H$30
Name inpal: Assumptions!$G$25:$G$30
Name month: Assumptions!$D$25:$D$30
Name pal: Assumptions!$H$25:$H$30
Name PPP: Assumptions!$F$25:$F$30
Name RowNum: _xlfn.LAMBDA(_xlpm.addresses,IF(ISNUMBER(_xlpm.addresses),INT(_xlpm.addresses/10^6),1*_xlfn.TEXTAFTER(UPPER(_xlpm.addresses),Alphabet(),-1)))
Name seg: Assumptions!$C$25:$C$30
Name starting_parc: Assumptions!$E$25:$E$30
Name Tlookup: _xlfn.LAMBDA(_xlpm.Table,_xlpm.Rowitem,_xlpm.Columnitem,INDEX(_xlpm.Table,_xlfn.XMATCH(_xlpm.Rowitem,_xlfn.TAKE(_xlpm.Table,,1)),_xlfn.XMATCH(_xlpm.Columnitem,_xlfn.TAKE(_xlpm.Table,1))))

Sheet Cover
C1: X-Logistic Services (XLS)
C2: 5-Year Monthly Financial Projection Model
C3: EBITDA Forecast | New Client Evaluation | 61-Month Projection Horizon
C6: Model Purpose: | D6: 5-year monthly EBITDA projection for strategic client decision-making
C7: New Client Toggle: | D7: Single-switch scenario — evaluate results with / without Tim Forward Brands
C8: Projection Period: | D8: January 2026 — December 2030 (61 months)
C9: Industries: | D9: Third-Party Logistics (3PL) | Retail | E-commerce | Industrial
C10: Service Lines: | D10: Inbound Handling · Outbound Picking · Outbound Handling · Storage
C11: Built By: | D11: Alicia Bruce
C12: Competition: | D12: Financial Modeling World Cup (FMWC)
A14: Built using a Financial Modeling World Cup case. Synthetic data — for portfolio demonstration purposes only.

Sheet Dashboard Summary
C1: X-Logistic Services (XLS) Dashboard
C4: With Tom Forward Brands* | D4: Off
C6: Total Revenue | D6: =SUM(Model!D20) -> 1.2415581e+08
C7: EBITDA | D7: =Model!D26 -> 55621678
C8: EBITDA Margin | D8: =D7/D6 -> 0.44799899
C9: Total Labor Costs | D9: =SUM(Model!H245:BO245) -> 59230113
C10: Temp Labor % | D10: =SUM(Model!H244:BO244)/'Dashboard Summary'!D9 -> 0.18824987
C11: Total Capex | D11: =SUM(Model!H326:BO326) -> 1254790.3
C15: Client Impact Summary
D16: Without Client | E16: With Client | F16: Gain/Loss
C17: Revenue | D17: =Assumptions!N25 -> 1.2415581e+08 | E17: =Assumptions!N24 -> 1.3652408e+08 | F17: =E17-D17 -> 12368269
C18: EBITDA | D18: =Assumptions!N29 -> 55621678 | E18: =Assumptions!N28 -> 61161159 | F18: =E18-D18 -> 5539480.9
C19: CAPEX | D19: =Assumptions!N33 -> 1254790.3 | E19: =Assumptions!N32 -> 2036472.6 | F19: =E19-D19 -> 781682.26
A21: *Toggle also powers model to turn on and off the addtion of Tom Forward Brands

Sheet Assumptions
K1: Calculations Added for Model
B2: X-Logistic Services (XLS)
B3: Inputs and Assumptions | M3: On
M4: Off
B5: 1. General Assumptions
B7: General Assumptions | F7: Staff Information
B8: Company Name | C8: [Date] | D8: X-Logistic Service | F8: Permanent staff | G8: [FTE] | H8: 174
B9: First Year of Projections | C9: [Date] | D9: 2026 | F9: Monthly FTE Hours | G9: [Hours/FTE] | H9: 160
B10: Annual Inflation | C10: [% p.a.] | D10: 0.03 | F10: Working shifts | G10: [#] | H10: 3
B11: SG&A | C11: [$/month] | D11: 62500 | F11: Permanent staff Cost | G11: [$/FTE/Month] | H11: 4160
B12: Energy Price | C12: [$/kWh] | D12: 0.18 | F12: Temporary staff Cost | G12: [$/FTE/Month] | H12: 5120
B13: Fixed COGS | C13: [$/month] | D13: 60000
F14: Staff Productivity per Activity | H14: Staff Productivity
B15: Service Prices | F15: Inbound unloading | G15: [Inbound Pallets/Hour] | H15: 12
B16: Inbound handling | C16: [$/Inbound Pallet] | D16: 4.5 | F16: Putaway to rack | G16: [Inbound Pallets/Hour] | H16: 10
B17: Outbound picking | C17: [$/Outbound Parcel] | D17: 0.35 | F17: Picking | G17: [Outbound Parcels/Hour] | H17: 180
B18: Outbound handling | C18: [$/Outbound Pallet] | D18: 5 | F18: Replenishment | G18: [Outbound Pallets/Hour] | H18: 15
B19: Storage rack | C19: [$/Pallet/Month] | D19: 6 | F19: Outbound loading | G19: [Outbound Pallets/Hour] | H19: 14
B22: 2. Client Data
L23: Revenue — With and Without Tim Forward Brands | N23: =Model!D20 -> 1.2415581e+08
B24: Client Name | C24: Segment | D24: Starting Month | E24: Monthly Outbound Parcels | F24: Parcels Per Pallet | G24: Initial Balance (Pallets) | H24: Assortment Growth Rate | I24: Contract Active | L24: With | M24: 1 | N24: 1.3652408e+08
B25: Michael’s Market Goods | C25: Retail | D25: 1 | E25: 375000 | F25: 18 | G25: 2400 | H25: 0.03 | I25: 1 | L25: Without | M25: 0 | N25: 1.2415581e+08
B26: Andrew Digital Commerce | C26: E-commerce | D26: 1 | E26: 450000 | F26: 30 | G26: 2100 | H26: 0.06 | I26: 1
B27: Anup Industrial Systems | C27: Industrial | D27: 1 | E27: 225000 | F27: 15 | G27: 1800 | H27: 0.01 | I27: 1 | L27: EBITDA — With and Without Tim Forward Brands | N27: =Model!D26 -> 55621678
B28: Joseph Retail Group | C28: Retail | D28: 1 | E28: 300000 | F28: 22 | G28: 2700 | H28: 0 | I28: 1 | L28: With | M28: 1 | N28: 61161159
B29: Dim Collective | C29: Retail | D29: 1 | E29: 125000 | F29: 25 | G29: 900 | H29: 0.08 | I29: 1 | L29: Without | M29: 0 | N29: 55621678
B30: Tim Forward Brands | C30: Retail | D30: 37 | E30: 250000 | F30: 15 | G30: 1500 | H30: 0.09 | I30: =IF('Dashboard Summary'!D4="Off",0,1) -> 0
L31: CapEx — With and Without Tim Forward Brands | N31: =SUM(Model!H326:BO326) -> 1254790.3
L32: With | M32: 1 | N32: 2036472.6
B33: 3. Customers Volume Growth | L33: Without | M33: 0 | N33: 1254790.3
B35: Client Name | D35: 1 | E35: 2 | F35: 3 | G35: 4 | H35: 5 | I35: 0 | K35: 1 | L35: 2 | M35: 3 | N35: 4 | O35: 5 | P35: 6
B36: Michael’s Market Goods | D36: 0.07 | E36: 0.05 | F36: 0.05 | G36: 0.03 | H36: 0.02 | I36: {=starting_parc} -> 375000 | K36: {=_xlfn.ANCHORARRAY(I36)*(1+D36:D41)} -> 401250 | L36: {=_xlfn.ANCHORARRAY(K36)*(1+E36:E41)} -> 421312.5 | M36: {=_xlfn.ANCHORARRAY(L36)*(1+F36:F41)} -> 442378.12 | N36: {=_xlfn.ANCHORARRAY(M36)*(1+G36:G41)} -> 455649.47 | O36: {=_xlfn.ANCHORARRAY(N36)*(1+H36:H41)} -> 464762.46 | P36: {=_xlfn.ANCHORARRAY(O36)*(1+H36:H41)} -> 474057.71
B37: Andrew Digital Commerce | D37: 0.12 | E37: 0.06 | F37: 0.02 | G37: 0 | H37: 0 | I37: 450000 | K37: 504000 | L37: 534240 | M37: 544924.8 | N37: 544924.8 | O37: 544924.8 | P37: 544924.8
B38: Anup Industrial Systems | D38: 0.01 | E38: 0.005 | F38: 0 | G38: -0.01 | H38: -0.015 | I38: 225000 | K38: 227250 | L38: 228386.25 | M38: 228386.25 | N38: 226102.39 | O38: 222710.85 | P38: 219370.19
B39: Joseph Retail Group | D39: -0.08 | E39: -0.04 | F39: -0.06 | G39: -0.08 | H39: -0.07 | I39: 300000 | K39: 276000 | L39: 264960 | M39: 249062.4 | N39: 229137.41 | O39: 213097.79 | P39: 198180.94
B40: Dim Collective | D40: 0.3 | E40: 0.15 | F40: 0.1 | G40: 0.06 | H40: 0.04 | I40: 125000 | K40: 162500 | L40: 186875 | M40: 205562.5 | N40: 217896.25 | O40: 226612.1 | P40: 235676.58
B41: Tim Forward Brands | D41: 0 | E41: 0 | F41: 0 | G41: 0.1448 | H41: 0.04 | I41: 250000 | K41: 250000 | L41: 250000 | M41: 250000 | N41: 286200 | O41: 297648 | P41: 309553.92
H42: CustomerVolumeGrowthIn
B44: 4. Seasonality per Client Segment
B46: Month | D46: Retail | E46: E-commerce | F46: Industrial | G46: SegmentsNameIn
...

Sheet Financial Model
B2: =Assumptions!D8 -> X-Logistic Service
C4: Period # | D4: 0 | E4: {=Timeline(Assumptions!D9,5)} -> 1 | F4: 2 | G4: 3 | H4: 4 | I4: 5 | J4: 6 | K4: 7 | L4: 8 | M4: 9 | N4: 10 | O4: 11 | P4: 12 | Q4: 13 | R4: 14 | S4: 15 | T4: 16 | U4: 17 | V4: 18 | W4: 19 | X4: 20 | Y4: 21 | Z4: 22 | AA4: 23 | AB4: 24 | AC4: 25 | AD4: 26 | AE4: 27 | AF4: 28 | AG4: 29 | AH4: 30 | AI4: 31 | AJ4: 32 | AK4: 33 | AL4: 34 | AM4: 35 | AN4: 36 | AO4: 37 | AP4: 38 | AQ4: 39 | AR4: 40 | AS4: 41 | AT4: 42 | AU4: 43 | AV4: 44 | AW4: 45 | AX4: 46 | AY4: 47 | AZ4: 48 | BA4: 49 | BB4: 50 | BC4: 51 | BD4: 52 | BE4: 53 | BF4: 54 | BG4: 55 | BH4: 56 | BI4: 57 | BJ4: 58 | BK4: 59 | BL4: 60 | BM4: =BL4+1 -> 61
C5: Start Date | D5: 45992 | E5: 46023 | F5: 46054 | G5: 46082 | H5: 46113 | I5: 46143 | J5: 46174 | K5: 46204 | L5: 46235 | M5: 46266 | N5: 46296 | O5: 46327 | P5: 46357 | Q5: 46388 | R5: 46419 | S5: 46447 | T5: 46478 | U5: 46508 | V5: 46539 | W5: 46569 | X5: 46600 | Y5: 46631 | Z5: 46661 | AA5: 46692 | AB5: 46722 | AC5: 46753 | AD5: 46784 | AE5: 46813 | AF5: 46844 | AG5: 46874 | AH5: 46905 | AI5: 46935 | AJ5: 46966 | AK5: 46997 | AL5: 47027 | AM5: 47058 | AN5: 47088 | AO5: 47119 | AP5: 47150 | AQ5: 47178 | AR5: 47209 | AS5: 47239 | AT5: 47270 | AU5: 47300 | AV5: 47331 | AW5: 47362 | AX5: 47392 | AY5: 47423 | AZ5: 47453 | BA5: 47484 | BB5: 47515 | BC5: 47543 | BD5: 47574 | BE5: 47604 | BF5: 47635 | BG5: 47665 | BH5: 47696 | BI5: 47727 | BJ5: 47757 | BK5: 47788 | BL5: 47818 | BM5: =BL5+31 -> 47849
C6: End Date | D6: =EOMONTH(D5,0) -> 46022 | E6: 46053 | F6: 46081 | G6: 46112 | H6: 46142 | I6: 46173 | J6: 46203 | K6: 46234 | L6: 46265 | M6: 46295 | N6: 46326 | O6: 46356 | P6: 46387 | Q6: 46418 | R6: 46446 | S6: 46477 | T6: 46507 | U6: 46538 | V6: 46568 | W6: 46599 | X6: 46630 | Y6: 46660 | Z6: 46691 | AA6: 46721 | AB6: 46752 | AC6: 46783 | AD6: 46812 | AE6: 46843 | AF6: 46873 | AG6: 46904 | AH6: 46934 | AI6: 46965 | AJ6: 46996 | AK6: 47026 | AL6: 47057 | AM6: 47087 | AN6: 47118 | AO6: 47149 | AP6: 47177 | AQ6: 47208 | AR6: 47238 | AS6: 47269 | AT6: 47299 | AU6: 47330 | AV6: 47361 | AW6: 47391 | AX6: 47422 | AY6: 47452 | AZ6: 47483 | BA6: 47514 | BB6: 47542 | BC6: 47573 | BD6: 47603 | BE6: 47634 | BF6: 47664 | BG6: 47695 | BH6: 47726 | BI6: 47756 | BJ6: 47787 | BK6: 47817 | BL6: 47848 | BM6: =EOMONTH(BM5,0) -> 47879
C7: Year | D7: =YEAR(D5) -> 2025 | E7: 2026 | F7: 2026 | G7: 2026 | H7: 2026 | I7: 2026 | J7: 2026 | K7: 2026 | L7: 2026 | M7: 2026 | N7: 2026 | O7: 2026 | P7: 2026 | Q7: 2027 | R7: 2027 | S7: 2027 | T7: 2027 | U7: 2027 | V7: 2027 | W7: 2027 | X7: 2027 | Y7: 2027 | Z7: 2027 | AA7: 2027 | AB7: 2027 | AC7: 2028 | AD7: 2028 | AE7: 2028 | AF7: 2028 | AG7: 2028 | AH7: 2028 | AI7: 2028 | AJ7: 2028 | AK7: 2028 | AL7: 2028 | AM7: 2028 | AN7: 2028 | AO7: 2029 | AP7: 2029 | AQ7: 2029 | AR7: 2029 | AS7: 2029 | AT7: 2029 | AU7: 2029 | AV7: 2029 | AW7: 2029 | AX7: 2029 | AY7: 2029 | AZ7: 2029 | BA7: 2030 | BB7: 2030 | BC7: 2030 | BD7: 2030 | BE7: 2030 | BF7: 2030 | BG7: 2030 | BH7: 2030 | BI7: 2030 | BJ7: 2030 | BK7: 2030 | BL7: 2030 | BM7: =YEAR(BM5) -> 2031
C8: Month # | D8: =MONTH(D5) -> 12 | E8: 1 | F8: 2 | G8: 3 | H8: 4 | I8: 5 | J8: 6 | K8: 7 | L8: 8 | M8: 9 | N8: 10 | O8: 11 | P8: 12 | Q8: 1 | R8: 2 | S8: 3 | T8: 4 | U8: 5 | V8: 6 | W8: 7 | X8: 8 | Y8: 9 | Z8: 10 | AA8: 11 | AB8: 12 | AC8: 1 | AD8: 2 | AE8: 3 | AF8: 4 | AG8: 5 | AH8: 6 | AI8: 7 | AJ8: 8 | AK8: 9 | AL8: 10 | AM8: 11 | AN8: 12 | AO8: 1 | AP8: 2 | AQ8: 3 | AR8: 4 | AS8: 5 | AT8: 6 | AU8: 7 | AV8: 8 | AW8: 9 | AX8: 10 | AY8: 11 | AZ8: 12 | BA8: 1 | BB8: 2 | BC8: 3 | BD8: 4 | BE8: 5 | BF8: 6 | BG8: 7 | BH8: 8 | BI8: 9 | BJ8: 10 | BK8: 11 | BL8: 12 | BM8: =MONTH(BM5) -> 1
C9: Quarter # | D9: 4 | E9: 1 | F9: 1 | G9: 1 | H9: 2 | I9: 2 | J9: 2 | K9: 3 | L9: 3 | M9: 3 | N9: 4 | O9: 4 | P9: 4 | Q9: 1 | R9: 1 | S9: 1 | T9: 2 | U9: 2 | V9: 2 | W9: 3 | X9: 3 | Y9: 3 | Z9: 4 | AA9: 4 | AB9: 4 | AC9: 1 | AD9: 1 | AE9: 1 | AF9: 2 | AG9: 2 | AH9: 2 | AI9: 3 | AJ9: 3 | AK9: 3 | AL9: 4 | AM9: 4 | AN9: 4 | AO9: 1 | AP9: 1 | AQ9: 1 | AR9: 2 | AS9: 2 | AT9: 2 | AU9: 3 | AV9: 3 | AW9: 3 | AX9: 4 | AY9: 4 | AZ9: 4 | BA9: 1 | BB9: 1 | BC9: 1 | BD9: 2 | BE9: 2 | BF9: 2 | BG9: 3 | BH9: 3 | BI9: 3 | BJ9: 4 | BK9: 4 | BL9: 4 | BM9: 4
C10: Quarter Name | D10: =YEAR(D5) & "-Q" & D9 -> 2025-Q4 | E10: 2026-Q1 | F10: 2026-Q1 | G10: 2026-Q1 | H10: 2026-Q2 | I10: 2026-Q2 | J10: 2026-Q2 | K10: 2026-Q3 | L10: 2026-Q3 | M10: 2026-Q3 | N10: 2026-Q4 | O10: 2026-Q4 | P10: 2026-Q4 | Q10: 2027-Q1 | R10: 2027-Q1 | S10: 2027-Q1 | T10: 2027-Q2 | U10: 2027-Q2 | V10: 2027-Q2 | W10: 2027-Q3 | X10: 2027-Q3 | Y10: 2027-Q3 | Z10: 2027-Q4 | AA10: 2027-Q4 | AB10: 2027-Q4 | AC10: 2028-Q1 | AD10: 2028-Q1 | AE10: 2028-Q1 | AF10: 2028-Q2 | AG10: 2028-Q2 | AH10: 2028-Q2 | AI10: 2028-Q3 | AJ10: 2028-Q3 | AK10: 2028-Q3 | AL10: 2028-Q4 | AM10: 2028-Q4 | AN10: 2028-Q4 | AO10: 2029-Q1 | AP10: 2029-Q1 | AQ10: 2029-Q1 | AR10: 2029-Q2 | AS10: 2029-Q2 | AT10: 2029-Q2 | AU10: 2029-Q3 | AV10: 2029-Q3 | AW10: 2029-Q3 | AX10: 2029-Q4 | AY10: 2029-Q4 | AZ10: 2029-Q4 | BA10: 2030-Q1 | BB10: 2030-Q1 | BC10: 2030-Q1 | BD10: 2030-Q2 | BE10: 2030-Q2 | BF10: 2030-Q2 | BG10: 2030-Q3 | BH10: 2030-Q3 | BI10: 2030-Q3 | BJ10: 2030-Q4 | BK10: 2030-Q4 | BL10: 2030-Q4 | BM10: =YEAR(BM5) & "-Q" & BM9 -> 2031-Q4
C11: Operating Year | D11: {=D7:BM7-D7} -> 0 | E11: 1 | F11: 1 | G11: 1 | H11: 1 | I11: 1 | J11: 1 | K11: 1 | L11: 1 | M11: 1 | N11: 1 | O11: 1 | P11: 1 | Q11: 2 | R11: 2 | S11: 2 | T11: 2 | U11: 2 | V11: 2 | W11: 2 | X11: 2 | Y11: 2 | Z11: 2 | AA11: 2 | AB11: 2 | AC11: 3 | AD11: 3 | AE11: 3 | AF11: 3 | AG11: 3 | AH11: 3 | AI11: 3 | AJ11: 3 | AK11: 3 | AL11: 3 | AM11: 3 | AN11: 3 | AO11: 4 | AP11: 4 | AQ11: 4 | AR11: 4 | AS11: 4 | AT11: 4 | AU11: 4 | AV11: 4 | AW11: 4 | AX11: 4 | AY11: 4 | AZ11: 4 | BA11: 5 | BB11: 5 | BC11: 5 | BD11: 5 | BE11: 5 | BF11: 5 | BG11: 5 | BH11: 5 | BI11: 5 | BJ11: 5 | BK11: 5 | BL11: 5 | BM11: 6
B14: 1. P&L Statement
C16: CPI | D16: {=(1+Assumptions!D10)^(D7:BM7-'Financial Model'!E7)} -> 0.97087379 | E16: 1 | F16: 1 | G16: 1 | H16: 1 | I16: 1 | J16: 1 | K16: 1 | L16: 1 | M16: 1 | N16: 1 | O16: 1 | P16: 1 | Q16: 1.03 | R16: 1.03 | S16: 1.03 | T16: 1.03 | U16: 1.03 | V16: 1.03 | W16: 1.03 | X16: 1.03 | Y16: 1.03 | Z16: 1.03 | AA16: 1.03 | AB16: 1.03 | AC16: 1.0609 | AD16: 1.0609 | AE16: 1.0609 | AF16: 1.0609 | AG16: 1.0609 | AH16: 1.0609 | AI16: 1.0609 | AJ16: 1.0609 | AK16: 1.0609 | AL16: 1.0609 | AM16: 1.0609 | AN16: 1.0609 | AO16: 1.092727 | AP16: 1.092727 | AQ16: 1.092727 | AR16: 1.092727 | AS16: 1.092727 | AT16: 1.092727 | AU16: 1.092727 | AV16: 1.092727 | AW16: 1.092727 | AX16: 1.092727 | AY16: 1.092727 | AZ16: 1.092727 | BA16: 1.1255088 | BB16: 1.1255088 | BC16: 1.1255088 | BD16: 1.1255088 | BE16: 1.1255088 | BF16: 1.1255088 | BG16: 1.1255088 | BH16: 1.1255088 | BI16: 1.1255088 | BJ16: 1.1255088 | BK16: 1.1255088 | BL16: 1.1255088 | BM16: 1.1592741
B18: Seasonality
C19: {=seg} -> Retail | E19: {=VLOOKUP($E$8:$BM$8,Assumptions!$B$47:$F$58,_xlfn.XMATCH('Financial Model'!$C19,Assumptions!$B$46:$F$46))} -> 0.75 | F19: 0.8 | G19: 0.85 | H19: 0.95 | I19: 1.1 | J19: 1.2 | K19: 0.9 | L19: 0.85 | M19: 1 | N19: 1.05 | O19: 1.2 | P19: 1.35 | Q19: 0.75 | R19: 0.8 | S19: 0.85 | T19: 0.95 | U19: 1.1 | V19: 1.2 | W19: 0.9 | X19: 0.85 | Y19: 1 | Z19: 1.05 | AA19: 1.2 | AB19: 1.35 | AC19: 0.75 | AD19: 0.8 | AE19: 0.85 | AF19: 0.95 | AG19: 1.1 | AH19: 1.2 | AI19: 0.9 | AJ19: 0.85 | AK19: 1 | AL19: 1.05 | AM19: 1.2 | AN19: 1.35 | AO19: 0.75 | AP19: 0.8 | AQ19: 0.85 | AR19: 0.95 | AS19: 1.1 | AT19: 1.2 | AU19: 0.9 | AV19: 0.85 | AW19: 1 | AX19: 1.05 | AY19: 1.2 | AZ19: 1.35 | BA19: 0.75 | BB19: 0.8 | BC19: 0.85 | BD19: 0.95 | BE19: 1.1 | BF19: 1.2 | BG19: 0.9 | BH19: 0.85 | BI19: 1 | BJ19: 1.05 | BK19: 1.2 | BL19: 1.35 | BM19: 0.75
C20: E-commerce | E20: {=VLOOKUP($E$8:$BM$8,Assumptions!$B$47:$F$58,_xlfn.XMATCH('Financial Model'!$C20,Assumptions!$B$46:$F$46))} -> 0.75 | F20: 0.65 | G20: 0.7 | H20: 0.75 | I20: 0.7 | J20: 0.75 | K20: 0.7 | L20: 0.9 | M20: 1.05 | N20: 1.1 | O20: 1.75 | P20: 2.2 | Q20: 0.75 | R20: 0.65 | S20: 0.7 | T20: 0.75 | U20: 0.7 | V20: 0.75 | W20: 0.7 | X20: 0.9 | Y20: 1.05 | Z20: 1.1 | AA20: 1.75 | AB20: 2.2 | AC20: 0.75 | AD20: 0.65 | AE20: 0.7 | AF20: 0.75 | AG20: 0.7 | AH20: 0.75 | AI20: 0.7 | AJ20: 0.9 | AK20: 1.05 | AL20: 1.1 | AM20: 1.75 | AN20: 2.2 | AO20: 0.75 | AP20: 0.65 | AQ20: 0.7 | AR20: 0.75 | AS20: 0.7 | AT20: 0.75 | AU20: 0.7 | AV20: 0.9 | AW20: 1.05 | AX20: 1.1 | AY20: 1.75 | AZ20: 2.2 | BA20: 0.75 | BB20: 0.65 | BC20: 0.7 | BD20: 0.75 | BE20: 0.7 | BF20: 0.75 | BG20: 0.7 | BH20: 0.9 | BI20: 1.05 | BJ20: 1.1 | BK20: 1.75 | BL20: 2.2 | BM20: 0.75
C21: Industrial | E21: {=VLOOKUP($E$8:$BM$8,Assumptions!$B$47:$F$58,_xlfn.XMATCH('Financial Model'!$C21,Assumptions!$B$46:$F$46))} -> 0.95 | F21: 0.95 | G21: 1 | H21: 1 | I21: 1 | J21: 1 | K21: 0.95 | L21: 0.9 | M21: 1.1 | N21: 1.1 | O21: 1.05 | P21: 1 | Q21: 0.95 | R21: 0.95 | S21: 1 | T21: 1 | U21: 1 | V21: 1 | W21: 0.95 | X21: 0.9 | Y21: 1.1 | Z21: 1.1 | AA21: 1.05 | AB21: 1 | AC21: 0.95 | AD21: 0.95 | AE21: 1 | AF21: 1 | AG21: 1 | AH21: 1 | AI21: 0.95 | AJ21: 0.9 | AK21: 1.1 | AL21: 1.1 | AM21: 1.05 | AN21: 1 | AO21: 0.95 | AP21: 0.95 | AQ21: 1 | AR21: 1 | AS21: 1 | AT21: 1 | AU21: 0.95 | AV21: 0.9 | AW21: 1.1 | AX21: 1.1 | AY21: 1.05 | AZ21: 1 | BA21: 0.95 | BB21: 0.95 | BC21: 1 | BD21: 1 | BE21: 1 | BF21: 1 | BG21: 0.95 | BH21: 0.9 | BI21: 1.1 | BJ21: 1.1 | BK21: 1.05 | BL21: 1 | BM21: 0.95
C22: Retail | E22: {=VLOOKUP($E$8:$BM$8,Assumptions!$B$47:$F$58,_xlfn.XMATCH('Financial Model'!$C22,Assumptions!$B$46:$F$46))} -> 0.75 | F22: 0.8 | G22: 0.85 | H22: 0.95 | I22: 1.1 | J22: 1.2 | K22: 0.9 | L22: 0.85 | M22: 1 | N22: 1.05 | O22: 1.2 | P22: 1.35 | Q22: 0.75 | R22: 0.8 | S22: 0.85 | T22: 0.95 | U22: 1.1 | V22: 1.2 | W22: 0.9 | X22: 0.85 | Y22: 1 | Z22: 1.05 | AA22: 1.2 | AB22: 1.35 | AC22: 0.75 | AD22: 0.8 | AE22: 0.85 | AF22: 0.95 | AG22: 1.1 | AH22: 1.2 | AI22: 0.9 | AJ22: 0.85 | AK22: 1 | AL22: 1.05 | AM22: 1.2 | AN22: 1.35 | AO22: 0.75 | AP22: 0.8 | AQ22: 0.85 | AR22: 0.95 | AS22: 1.1 | AT22: 1.2 | AU22: 0.9 | AV22: 0.85 | AW22: 1 | AX22: 1.05 | AY22: 1.2 | AZ22: 1.35 | BA22: 0.75 | BB22: 0.8 | BC22: 0.85 | BD22: 0.95 | BE22: 1.1 | BF22: 1.2 | BG22: 0.9 | BH22: 0.85 | BI22: 1 | BJ22: 1.05 | BK22: 1.2 | BL22: 1.35 | BM22: 0.75
C23: Retail | E23: {=VLOOKUP($E$8:$BM$8,Assumptions!$B$47:$F$58,_xlfn.XMATCH('Financial Model'!$C23,Assumptions!$B$46:$F$46))} -> 0.75 | F23: 0.8 | G23: 0.85 | H23: 0.95 | I23: 1.1 | J23: 1.2 | K23: 0.9 | L23: 0.85 | M23: 1 | N23: 1.05 | O23: 1.2 | P23: 1.35 | Q23: 0.75 | R23: 0.8 | S23: 0.85 | T23: 0.95 | U23: 1.1 | V23: 1.2 | W23: 0.9 | X23: 0.85 | Y23: 1 | Z23: 1.05 | AA23: 1.2 | AB23: 1.35 | AC23: 0.75 | AD23: 0.8 | AE23: 0.85 | AF23: 0.95 | AG23: 1.1 | AH23: 1.2 | AI23: 0.9 | AJ23: 0.85 | AK23: 1 | AL23: 1.05 | AM23: 1.2 | AN23: 1.35 | AO23: 0.75 | AP23: 0.8 | AQ23: 0.85 | AR23: 0.95 | AS23: 1.1 | AT23: 1.2 | AU23: 0.9 | AV23: 0.85 | AW23: 1 | AX23: 1.05 | AY23: 1.2 | AZ23: 1.35 | BA23: 0.75 | BB23: 0.8 | BC23: 0.85 | BD23: 0.95 | BE23: 1.1 | BF23: 1.2 | BG23: 0.9 | BH23: 0.85 | BI23: 1 | BJ23: 1.05 | BK23: 1.2 | BL23: 1.35 | BM23: 0.75
C24: Retail | E24: {=VLOOKUP($E$8:$BM$8,Assumptions!$B$47:$F$58,_xlfn.XMATCH('Financial Model'!$C24,Assumptions!$B$46:$F$46))} -> 0.75 | F24: 0.8 | G24: 0.85 | H24: 0.95 | I24: 1.1 | J24: 1.2 | K24: 0.9 | L24: 0.85 | M24: 1 | N24: 1.05 | O24: 1.2 | P24: 1.35 | Q24: 0.75 | R24: 0.8 | S24: 0.85 | T24: 0.95 | U24: 1.1 | V24: 1.2 | W24: 0.9 | X24: 0.85 | Y24: 1 | Z24: 1.05 | AA24: 1.2 | AB24: 1.35 | AC24: 0.75 | AD24: 0.8 | AE24: 0.85 | AF24: 0.95 | AG24: 1.1 | AH24: 1.2 | AI24: 0.9 | AJ24: 0.85 | AK24: 1 | AL24: 1.05 | AM24: 1.2 | AN24: 1.35 | AO24: 0.75 | AP24: 0.8 | AQ24: 0.85 | AR24: 0.95 | AS24: 1.1 | AT24: 1.2 | AU24: 0.9 | AV24: 0.85 | AW24: 1 | AX24: 1.05 | AY24: 1.2 | AZ24: 1.35 | BA24: 0.75 | BB24: 0.8 | BC24: 0.85 | BD24: 0.95 | BE24: 1.1 | BF24: 1.2 | BG24: 0.9 | BH24: 0.85 | BI24: 1 | BJ24: 1.05 | BK24: 1.2 | BL24: 1.35 | BM24: 0.75
B26: Client Volume Growth
C28: {=cust} -> Michael’s Market Goods | D28: =Assumptions!E25 -> 375000 | E28: {=(1+(_xlfn.XLOOKUP(E$11,Assumptions!$B$35:$H$35,_xlfn.XLOOKUP($C28,Assumptions!$B$36:$B$41,Assumptions!$B$36:$H$41),,-1)))*$D28} -> 401250 | F28: {=(1+(_xlfn.XLOOKUP(F$11,Assumptions!$B$35:$H$35,_xlfn.XLOOKUP($C28,Assumptions!$B$36:$B$41,Assumptions!$B$36:$H$41),,-1)))*$D28} -> 401250 | G28: {=(1+(_xlfn.XLOOKUP(G$11,Assumptions!$B$35:$H$35,_xlfn.XLOOKUP($C28,Assumptions!$B$36:$B$41,Assumptions!$B$36:$H$41),,-1)))*$D28} -> 401250 | H28: {=(1+(_xlfn.XLOOKUP(H$11,Assumptions!$B$35:$H$35,_xlfn.XLOOKUP($C28,Assumptions!$B$36:$B$41,Assumptions!$B$36:$H$41),,-1)))*$D28} -> 401250 | I28: {=(1+(_xlfn.XLOOKUP(I$11,Assumptions!$B$35:$H$35,_xlfn.XLOOKUP($C28,Assumptions!$B$36:$B$41,Assumptions!$B$36:$H$41),,-1)))*$D28} -> 401250 | J28: {=(1+(_xlfn.XLOOKUP(J$11,Assumptions!$B$35:$H$35,_xlfn.XLOOKUP($C28,Assumptions!$B$36:$B$41,Assumptions!$B$36:$H$41),,-1)))*$D28} -> 401250 | K28: {=(1+(_xlfn.XLOOKUP(K$11,Assumptions!$B$35:$H$35,_xlfn.XLOOKUP($C28,Assumptions!$B$36:$B$41,Assumptions!$B$36:$H$41),,-1)))*$D28} -> 401250 | L28: {=(1+(_xlfn.XLOOKUP(L$11,Assumptions!$B$35:$H$35,_xlfn.XLOOKUP($C28,Assumptions!$B$36:$B$41,Assumptions!$B$36:$H$41),,-1)))*$D28} -> 401250 | ... BM28: {=(1+(_xlfn.XLOOKUP(BM$11,Assumptions!$B$35:$H$35,_xlfn.XLOOKUP($C28,Assumptions!$B$36:$B$41,Assumptions!$B$36:$H$41),,-1)))*$D28} -> 382500 | BN28: {=_xlfn.XLOOKUP(BN$11,Assumptions!$B$35:$H$35,_xlfn.XLOOKUP($C28,Assumptions!$B$36:$B$41,Assumptions!$B$36:$H$41))} -> 0 | BO28: {=_xlfn.XLOOKUP(BO$11,Assumptions!$B$35:$H$35,_xlfn.XLOOKUP($C28,Assumptions!$B$36:$B$41,Assumptions!$B$36:$H$41))} -> 0 | BP28: {=_xlfn.XLOOKUP(BP$11,Assumptions!$B$35:$H$35,_xlfn.XLOOKUP($C28,Assumptions!$B$36:$B$41,Assumptions!$B$36:$H$41))} -> 0 | BQ28: {=_xlfn.XLOOKUP(BQ$11,Assumptions!$B$35:$H$35,_xlfn.XLOOKUP($C28,Assumptions!$B$36:$B$41,Assumptions!$B$36:$H$41))} -> 0 | BR28: {=_xlfn.XLOOKUP(BR$11,Assumptions!$B$35:$H$35,_xlfn.XLOOKUP($C28,Assumptions!$B$36:$B$41,Assumptions!$B$36:$H$41))} -> 0 | BS28: {=_xlfn.XLOOKUP(BS$11,Assumptions!$B$35:$H$35,_xlfn.XLOOKUP($C28,Assumptions!$B$36:$B$41,Assumptions!$B$36:$H$41))} -> 0 | BT28: {=_xlfn.XLOOKUP(BT$11,Assumptions!$B$35:$H$35,_xlfn.XLOOKUP($C28,Assumptions!$B$36:$B$41,Assumptions!$B$36:$H$41))} -> 0 | BU28: {=_xlfn.XLOOKUP(BU$11,Assumptions!$B$35:$H$35,_xlfn.XLOOKUP($C28,Assumptions!$B$36:$B$41,Assumptions!$B$36:$H$41))} -> 0 | ... XFD28: {=_xlfn.XLOOKUP(XFD$11,Assumptions!$B$35:$H$35,_xlfn.XLOOKUP($C28,Assumptions!$B$36:$B$41,Assumptions!$B$36:$H$41))} -> 0
C29: Andrew Digital Commerce | D29: =Assumptions!E26 -> 450000 | E29: {=(1+(_xlfn.XLOOKUP(E$11,Assumptions!$B$35:$H$35,_xlfn.XLOOKUP($C29,Assumptions!$B$36:$B$41,Assumptions!$B$36:$H$41),,-1)))*$D29} -> 504000 | F29: {=(1+(_xlfn.XLOOKUP(F$11,Assumptions!$B$35:$H$35,_xlfn.XLOOKUP($C29,Assumptions!$B$36:$B$41,Assumptions!$B$36:$H$41),,-1)))*$D29} -> 504000 | G29: {=(1+(_xlfn.XLOOKUP(G$11,Assumptions!$B$35:$H$35,_xlfn.XLOOKUP($C29,Assumptions!$B$36:$B$41,Assumptions!$B$36:$H$41),,-1)))*$D29} -> 504000 | H29: {=(1+(_xlfn.XLOOKUP(H$11,Assumptions!$B$35:$H$35,_xlfn.XLOOKUP($C29,Assumptions!$B$36:$B$41,Assumptions!$B$36:$H$41),,-1)))*$D29} -> 504000 | I29: {=(1+(_xlfn.XLOOKUP(I$11,Assumptions!$B$35:$H$35,_xlfn.XLOOKUP($C29,Assumptions!$B$36:$B$41,Assumptions!$B$36:$H$41),,-1)))*$D29} -> 504000 | J29: {=(1+(_xlfn.XLOOKUP(J$11,Assumptions!$B$35:$H$35,_xlfn.XLOOKUP($C29,Assumptions!$B$36:$B$41,Assumptions!$B$36:$H$41),,-1)))*$D29} -> 504000 | K29: {=(1+(_xlfn.XLOOKUP(K$11,Assumptions!$B$35:$H$35,_xlfn.XLOOKUP($C29,Assumptions!$B$36:$B$41,Assumptions!$B$36:$H$41),,-1)))*$D29} -> 504000 | L29: {=(1+(_xlfn.XLOOKUP(L$11,Assumptions!$B$35:$H$35,_xlfn.XLOOKUP($C29,Assumptions!$B$36:$B$41,Assumptions!$B$36:$H$41),,-1)))*$D29} -> 504000 | ... BM29: {=(1+(_xlfn.XLOOKUP(BM$11,Assumptions!$B$35:$H$35,_xlfn.XLOOKUP($C29,Assumptions!$B$36:$B$41,Assumptions!$B$36:$H$41),,-1)))*$D29} -> 450000
C30: Anup Industrial Systems | D30: =Assumptions!E27 -> 225000 | E30: {=(1+(_xlfn.XLOOKUP(E$11,Assumptions!$B$35:$H$35,_xlfn.XLOOKUP($C30,Assumptions!$B$36:$B$41,Assumptions!$B$36:$H$41),,-1)))*$D30} -> 227250 | F30: {=(1+(_xlfn.XLOOKUP(F$11,Assumptions!$B$35:$H$35,_xlfn.XLOOKUP($C30,Assumptions!$B$36:$B$41,Assumptions!$B$36:$H$41),,-1)))*$D30} -> 227250 | G30: {=(1+(_xlfn.XLOOKUP(G$11,Assumptions!$B$35:$H$35,_xlfn.XLOOKUP($C30,Assumptions!$B$36:$B$41,Assumptions!$B$36:$H$41),,-1)))*$D30} -> 227250 | H30: {=(1+(_xlfn.XLOOKUP(H$11,Assumptions!$B$35:$H$35,_xlfn.XLOOKUP($C30,Assumptions!$B$36:$B$41,Assumptions!$B$36:$H$41),,-1)))*$D30} -> 227250 | I30: {=(1+(_xlfn.XLOOKUP(I$11,Assumptions!$B$35:$H$35,_xlfn.XLOOKUP($C30,Assumptions!$B$36:$B$41,Assumptions!$B$36:$H$41),,-1)))*$D30} -> 227250 | J30: {=(1+(_xlfn.XLOOKUP(J$11,Assumptions!$B$35:$H$35,_xlfn.XLOOKUP($C30,Assumptions!$B$36:$B$41,Assumptions!$B$36:$H$41),,-1)))*$D30} -> 227250 | K30: {=(1+(_xlfn.XLOOKUP(K$11,Assumptions!$B$35:$H$35,_xlfn.XLOOKUP($C30,Assumptions!$B$36:$B$41,Assumptions!$B$36:$H$41),,-1)))*$D30} -> 227250 | L30: {=(1+(_xlfn.XLOOKUP(L$11,Assumptions!$B$35:$H$35,_xlfn.XLOOKUP($C30,Assumptions!$B$36:$B$41,Assumptions!$B$36:$H$41),,-1)))*$D30} -> 227250 | ... BM30: {=(1+(_xlfn.XLOOKUP(BM$11,Assumptions!$B$35:$H$35,_xlfn.XLOOKUP($C30,Assumptions!$B$36:$B$41,Assumptions!$B$36:$H$41),,-1)))*$D30} -> 221625
C31: Joseph Retail Group | D31: =Assumptions!E28 -> 300000 | E31: {=(1+(_xlfn.XLOOKUP(E$11,Assumptions!$B$35:$H$35,_xlfn.XLOOKUP($C31,Assumptions!$B$36:$B$41,Assumptions!$B$36:$H$41),,-1)))*$D31} -> 276000 | F31: {=(1+(_xlfn.XLOOKUP(F$11,Assumptions!$B$35:$H$35,_xlfn.XLOOKUP($C31,Assumptions!$B$36:$B$41,Assumptions!$B$36:$H$41),,-1)))*$D31} -> 276000 | G31: {=(1+(_xlfn.XLOOKUP(G$11,Assumptions!$B$35:$H$35,_xlfn.XLOOKUP($C31,Assumptions!$B$36:$B$41,Assumptions!$B$36:$H$41),,-1)))*$D31} -> 276000 | H31: {=(1+(_xlfn.XLOOKUP(H$11,Assumptions!$B$35:$H$35,_xlfn.XLOOKUP($C31,Assumptions!$B$36:$B$41,Assumptions!$B$36:$H$41),,-1)))*$D31} -> 276000 | I31: {=(1+(_xlfn.XLOOKUP(I$11,Assumptions!$B$35:$H$35,_xlfn.XLOOKUP($C31,Assumptions!$B$36:$B$41,Assumptions!$B$36:$H$41),,-1)))*$D31} -> 276000 | J31: {=(1+(_xlfn.XLOOKUP(J$11,Assumptions!$B$35:$H$35,_xlfn.XLOOKUP($C31,Assumptions!$B$36:$B$41,Assumptions!$B$36:$H$41),,-1)))*$D31} -> 276000 | K31: {=(1+(_xlfn.XLOOKUP(K$11,Assumptions!$B$35:$H$35,_xlfn.XLOOKUP($C31,Assumptions!$B$36:$B$41,Assumptions!$B$36:$H$41),,-1)))*$D31} -> 276000 | L31: {=(1+(_xlfn.XLOOKUP(L$11,Assumptions!$B$35:$H$35,_xlfn.XLOOKUP($C31,Assumptions!$B$36:$B$41,Assumptions!$B$36:$H$41),,-1)))*$D31} -> 276000 | ... BM31: {=(1+(_xlfn.XLOOKUP(BM$11,Assumptions!$B$35:$H$35,_xlfn.XLOOKUP($C31,Assumptions!$B$36:$B$41,Assumptions!$B$36:$H$41),,-1)))*$D31} -> 279000
C32: Dim Collective | D32: =Assumptions!E29 -> 125000 | E32: {=(1+(_xlfn.XLOOKUP(E$11,Assumptions!$B$35:$H$35,_xlfn.XLOOKUP($C32,Assumptions!$B$36:$B$41,Assumptions!$B$36:$H$41),,-1)))*$D32} -> 162500 | F32: {=(1+(_xlfn.XLOOKUP(F$11,Assumptions!$B$35:$H$35,_xlfn.XLOOKUP($C32,Assumptions!$B$36:$B$41,Assumptions!$B$36:$H$41),,-1)))*$D32} -> 162500 | G32: {=(1+(_xlfn.XLOOKUP(G$11,Assumptions!$B$35:$H$35,_xlfn.XLOOKUP($C32,Assumptions!$B$36:$B$41,Assumptions!$B$36:$H$41),,-1)))*$D32} -> 162500 | H32: {=(1+(_xlfn.XLOOKUP(H$11,Assumptions!$B$35:$H$35,_xlfn.XLOOKUP($C32,Assumptions!$B$36:$B$41,Assumptions!$B$36:$H$41),,-1)))*$D32} -> 162500 | I32: {=(1+(_xlfn.XLOOKUP(I$11,Assumptions!$B$35:$H$35,_xlfn.XLOOKUP($C32,Assumptions!$B$36:$B$41,Assumptions!$B$36:$H$41),,-1)))*$D32} -> 162500 | J32: {=(1+(_xlfn.XLOOKUP(J$11,Assumptions!$B$35:$H$35,_xlfn.XLOOKUP($C32,Assumptions!$B$36:$B$41,Assumptions!$B$36:$H$41),,-1)))*$D32} -> 162500 | K32: {=(1+(_xlfn.XLOOKUP(K$11,Assumptions!$B$35:$H$35,_xlfn.XLOOKUP($C32,Assumptions!$B$36:$B$41,Assumptions!$B$36:$H$41),,-1)))*$D32} -> 162500 | L32: {=(1+(_xlfn.XLOOKUP(L$11,Assumptions!$B$35:$H$35,_xlfn.XLOOKUP($C32,Assumptions!$B$36:$B$41,Assumptions!$B$36:$H$41),,-1)))*$D32} -> 162500 | ... BM32: {=(1+(_xlfn.XLOOKUP(BM$11,Assumptions!$B$35:$H$35,_xlfn.XLOOKUP($C32,Assumptions!$B$36:$B$41,Assumptions!$B$36:$H$41),,-1)))*$D32} -> 130000
C33: Tim Forward Brands | D33: =Assumptions!E30 -> 250000 | E33: {=(1+(_xlfn.XLOOKUP(E$11,Assumptions!$B$35:$H$35,_xlfn.XLOOKUP($C33,Assumptions!$B$36:$B$41,Assumptions!$B$36:$H$41),,-1)))*$D33} -> 250000 | F33: {=(1+(_xlfn.XLOOKUP(F$11,Assumptions!$B$35:$H$35,_xlfn.XLOOKUP($C33,Assumptions!$B$36:$B$41,Assumptions!$B$36:$H$41),,-1)))*$D33} -> 250000 | G33: {=(1+(_xlfn.XLOOKUP(G$11,Assumptions!$B$35:$H$35,_xlfn.XLOOKUP($C33,Assumptions!$B$36:$B$41,Assumptions!$B$36:$H$41),,-1)))*$D33} -> 250000 | H33: {=(1+(_xlfn.XLOOKUP(H$11,Assumptions!$B$35:$H$35,_xlfn.XLOOKUP($C33,Assumptions!$B$36:$B$41,Assumptions!$B$36:$H$41),,-1)))*$D33} -> 250000 | I33: {=(1+(_xlfn.XLOOKUP(I$11,Assumptions!$B$35:$H$35,_xlfn.XLOOKUP($C33,Assumptions!$B$36:$B$41,Assumptions!$B$36:$H$41),,-1)))*$D33} -> 250000 | J33: {=(1+(_xlfn.XLOOKUP(J$11,Assumptions!$B$35:$H$35,_xlfn.XLOOKUP($C33,Assumptions!$B$36:$B$41,Assumptions!$B$36:$H$41),,-1)))*$D33} -> 250000 | K33: {=(1+(_xlfn.XLOOKUP(K$11,Assumptions!$B$35:$H$35,_xlfn.XLOOKUP($C33,Assumptions!$B$36:$B$41,Assumptions!$B$36:$H$41),,-1)))*$D33} -> 250000 | L33: {=(1+(_xlfn.XLOOKUP(L$11,Assumptions!$B$35:$H$35,_xlfn.XLOOKUP($C33,Assumptions!$B$36:$B$41,Assumptions!$B$36:$H$41),,-1)))*$D33} -> 250000 | ... BM33: {=(1+(_xlfn.XLOOKUP(BM$11,Assumptions!$B$35:$H$35,_xlfn.XLOOKUP($C33,Assumptions!$B$36:$B$41,Assumptions!$B$36:$H$41),,-1)))*$D33} -> 260000

Sheet Model
B2: Tom Forward Brands Currently | C2: ='Dashboard Summary'!D4 -> Off
B4: X-Logistic Services (XLS) - 5 Year Financial Projection
C7: Period Number | G7: {=_xlfn.SEQUENCE(,62,0)} -> 0 | H7: 1 | I7: 2 | J7: 3 | K7: 4 | L7: 5 | M7: 6 | N7: 7 | O7: 8 | P7: 9 | Q7: 10 | R7: 11 | S7: 12 | T7: 13 | U7: 14 | V7: 15 | W7: 16 | X7: 17 | Y7: 18 | Z7: 19 | AA7: 20 | AB7: 21 | AC7: 22 | AD7: 23 | AE7: 24 | AF7: 25 | AG7: 26 | AH7: 27 | AI7: 28 | AJ7: 29 | AK7: 30 | AL7: 31 | AM7: 32 | AN7: 33 | AO7: 34 | AP7: 35 | AQ7: 36 | AR7: 37 | AS7: 38 | AT7: 39 | AU7: 40 | AV7: 41 | AW7: 42 | AX7: 43 | AY7: 44 | AZ7: 45 | BA7: 46 | BB7: 47 | BC7: 48 | BD7: 49 | BE7: 50 | BF7: 51 | BG7: 52 | BH7: 53 | BI7: 54 | BJ7: 55 | BK7: 56 | BL7: 57 | BM7: 58 | BN7: 59 | BO7: 60 | BP7: 61
C8: Period End | G8: =EOMONTH(DATE(2025,12,1),G7) -> 46022 | H8: =EOMONTH(DATE(2025,12,1),H7) -> 46053 | I8: =EOMONTH(DATE(2025,12,1),I7) -> 46081 | J8: =EOMONTH(DATE(2025,12,1),J7) -> 46112 | K8: =EOMONTH(DATE(2025,12,1),K7) -> 46142 | L8: =EOMONTH(DATE(2025,12,1),L7) -> 46173 | M8: =EOMONTH(DATE(2025,12,1),M7) -> 46203 | N8: =EOMONTH(DATE(2025,12,1),N7) -> 46234 | ... BP8: =EOMONTH(DATE(2025,12,1),BP7) -> 47879
C9: Month | G9: {=MONTH(G8:BP8)} -> 12 | H9: 1 | I9: 2 | J9: 3 | K9: 4 | L9: 5 | M9: 6 | N9: 7 | O9: 8 | P9: 9 | Q9: 10 | R9: 11 | S9: 12 | T9: 1 | U9: 2 | V9: 3 | W9: 4 | X9: 5 | Y9: 6 | Z9: 7 | AA9: 8 | AB9: 9 | AC9: 10 | AD9: 11 | AE9: 12 | AF9: 1 | AG9: 2 | AH9: 3 | AI9: 4 | AJ9: 5 | AK9: 6 | AL9: 7 | AM9: 8 | AN9: 9 | AO9: 10 | AP9: 11 | AQ9: 12 | AR9: 1 | AS9: 2 | AT9: 3 | AU9: 4 | AV9: 5 | AW9: 6 | AX9: 7 | AY9: 8 | AZ9: 9 | BA9: 10 | BB9: 11 | BC9: 12 | BD9: 1 | BE9: 2 | BF9: 3 | BG9: 4 | BH9: 5 | BI9: 6 | BJ9: 7 | BK9: 8 | BL9: 9 | BM9: 10 | BN9: 11 | BO9: 12 | BP9: 1
C10: Year | G10: {=YEAR(G8:BP8)} -> 2025 | H10: 2026 | I10: 2026 | J10: 2026 | K10: 2026 | L10: 2026 | M10: 2026 | N10: 2026 | O10: 2026 | P10: 2026 | Q10: 2026 | R10: 2026 | S10: 2026 | T10: 2027 | U10: 2027 | V10: 2027 | W10: 2027 | X10: 2027 | Y10: 2027 | Z10: 2027 | AA10: 2027 | AB10: 2027 | AC10: 2027 | AD10: 2027 | AE10: 2027 | AF10: 2028 | AG10: 2028 | AH10: 2028 | AI10: 2028 | AJ10: 2028 | AK10: 2028 | AL10: 2028 | AM10: 2028 | AN10: 2028 | AO10: 2028 | AP10: 2028 | AQ10: 2028 | AR10: 2029 | AS10: 2029 | AT10: 2029 | AU10: 2029 | AV10: 2029 | AW10: 2029 | AX10: 2029 | AY10: 2029 | AZ10: 2029 | BA10: 2029 | BB10: 2029 | BC10: 2029 | BD10: 2030 | BE10: 2030 | BF10: 2030 | BG10: 2030 | BH10: 2030 | BI10: 2030 | BJ10: 2030 | BK10: 2030 | BL10: 2030 | BM10: 2030 | BN10: 2030 | BO10: 2030 | BP10: 2031
B13: P&L Statement
C20: Net Revenue | D20: =SUM(H20:BO20) -> 1.2415581e+08 | F20: [$] | H20: {=_xlfn.ANCHORARRAY(H197)} -> 1061089 | I20: 1110288.3 | J20: 1221309.1 | K20: 1354238.9 | L20: 1483298.3 | M20: 1409043.1 | N20: 1256633.2 | O20: 1415401.8 | P20: 1606767.1 | Q20: 1840443.4 | R20: 2240213.9 | S20: 1924048.3 | T20: 1318859.8 | U20: 1371272.9 | V20: 1490747 | W20: 1633609 | X20: 1772207.4 | Y20: 1693530.1 | Z20: 1531875 | AA20: 1703155.7 | AB20: 1908451.3 | AC20: 2162319.1 | AD20: 2596936.1 | AE20: 2245744.6 | AF20: 1581562.3 | AG20: 1637222.6 | AH20: 1763589.8 | AI20: 1915171.5 | AJ20: 2062321.9 | AK20: 1979402.3 | AL20: 1808806.8 | AM20: 1989059.9 | AN20: 2205348.3 | AO20: 2473558 | AP20: 2932311.2 | AQ20: 2549563 | AR20: 1840000.9 | AS20: 1897975.4 | AT20: 2029022.5 | AU20: 2186585.4 | AV20: 2339620.2 | AW20: 2253840 | AX20: 2077247.9 | AY20: 2263443.1 | AZ20: 2487085.8 | BA20: 2764705.7 | BB20: 3239126.5 | BC20: 2840849.8 | BD20: 2111597 | BE20: 2171564.6 | BF20: 2306914.9 | BG20: 2469906.5 | BH20: 2628248.6 | BI20: 2539906.3 | BJ20: 2358005.4 | BK20: 2549839.4 | BL20: 2780255.6 | BM20: 3066997.7 | BN20: 3556761 | BO20: 3146909.8 | BP20: 0
C21: COGS (Cost of Goods Sold) | D21: =SUM(H21:BO21) -> -64552280 | F21: [$] | H21: {=-_xlfn.ANCHORARRAY(H352)} -> -801649.18 | I21: -802195.51 | J21: -821967.12 | K21: -897137.9 | L21: -970470.07 | M21: -926125.73 | N21: -814733.39 | O21: -898439.02 | P21: -1014312.2 | Q21: -1142816.1 | R21: -1378488 | S21: -1198947.2 | T21: -834927.38 | U21: -835504.5 | V21: -879418.04 | W21: -959966.86 | X21: -1038406 | Y21: -991100.93 | Z21: -872512.54 | AA21: -962746.76 | AB21: -1086654 | AC21: -1226058.1 | AD21: -1482046.9 | AE21: -1282310.3 | AF21: -891261.67 | AG21: -891871.54 | AH21: -919672.22 | AI21: -1004968.5 | AJ21: -1088061.1 | AK21: -1037969.2 | AL21: -912613.72 | AM21: -1007384.3 | AN21: -1137649.2 | AO21: -1284734.8 | AP21: -1554705.1 | AQ21: -1336740.9 | AR21: -931679.15 | AS21: -932311.82 | AT21: -946630.76 | AU21: -1035139.2 | AV21: -1121387.3 | AW21: -1069354.9 | AX21: -939404.31 | AY21: -1037120.5 | AZ21: -1171588.5 | BA21: -1323654 | BB21: -1602623.7 | BC21: -1375582.3 | BD21: -964278.58 | BE21: -964930.8 | BF21: -972503.32 | BG21: -1063938.7 | BH21: -1153039.2 | BI21: -1099280.9 | BJ21: -966296.63 | BK21: -1065794.6 | BL21: -1204136.2 | BM21: -1361062.4 | BN21: -1648892.3 | BO21: -1415084.5
C22: Gross Profit | D22: =D20+D21 -> 59603530 | H22: {=+H20:BO20+H21:BO21} -> 259439.86 | I22: 308092.75 | J22: 399342.02 | K22: 457100.97 | L22: 512828.23 | M22: 482917.39 | N22: 441899.76 | O22: 516962.77 | P22: 592454.93 | Q22: 697627.3 | R22: 861725.93 | S22: 725101.18 | T22: 483932.42 | U22: 535768.41 | V22: 611328.99 | W22: 673642.12 | X22: 733801.44 | Y22: 702429.19 | Z22: 659362.44 | AA22: 740408.98 | AB22: 821797.29 | AC22: 936260.93 | AD22: 1114889.3 | AE22: 963434.23 | AF22: 690300.66 | AG22: 745351.07 | AH22: 843917.58 | AI22: 910203.06 | AJ22: 974260.8 | AK22: 941433.06 | AL22: 896193.11 | AM22: 981675.55 | AN22: 1067699.1 | AO22: 1188823.2 | AP22: 1377606.1 | AQ22: 1212822.1 | AR22: 908321.73 | AS22: 965663.62 | AT22: 1082391.8 | AU22: 1151446.2 | AV22: 1218232.8 | AW22: 1184485 | AX22: 1137843.6 | AY22: 1226322.6 | AZ22: 1315497.2 | BA22: 1441051.6 | BB22: 1636502.8 | BC22: 1465267.5 | BD22: 1147318.4 | BE22: 1206633.8 | BF22: 1334411.6 | BG22: 1405967.8 | BH22: 1475209.5 | BI22: 1440625.3 | BJ22: 1391708.8 | BK22: 1484044.8 | BL22: 1576119.3 | BM22: 1705935.4 | BN22: 1907868.7 | BO22: 1731825.3
C24: SG&A (Sales, General & Administrative Expense) | D24: =SUM(H24:BO24) -> -3981851.9 | F24: [$] | H24: {=-_xlfn.ANCHORARRAY(H354)} -> -62500 | I24: -62500 | J24: -62500 | K24: -62500 | L24: -62500 | M24: -62500 | N24: -62500 | O24: -62500 | P24: -62500 | Q24: -62500 | R24: -62500 | S24: -62500 | T24: -64375 | U24: -64375 | V24: -64375 | W24: -64375 | X24: -64375 | Y24: -64375 | Z24: -64375 | AA24: -64375 | AB24: -64375 | AC24: -64375 | AD24: -64375 | AE24: -64375 | AF24: -66306.25 | AG24: -66306.25 | AH24: -66306.25 | AI24: -66306.25 | AJ24: -66306.25 | AK24: -66306.25 | AL24: -66306.25 | AM24: -66306.25 | AN24: -66306.25 | AO24: -66306.25 | AP24: -66306.25 | AQ24: -66306.25 | AR24: -68295.438 | AS24: -68295.438 | AT24: -68295.438 | AU24: -68295.438 | AV24: -68295.438 | AW24: -68295.438 | AX24: -68295.438 | AY24: -68295.438 | AZ24: -68295.438 | BA24: -68295.438 | BB24: -68295.438 | BC24: -68295.438 | BD24: -70344.301 | BE24: -70344.301 | BF24: -70344.301 | BG24: -70344.301 | BH24: -70344.301 | BI24: -70344.301 | BJ24: -70344.301 | BK24: -70344.301 | BL24: -70344.301 | BM24: -70344.301 | BN24: -70344.301 | BO24: -70344.301
C26: EBITDA | D26: =SUM(H26:BO26) -> 55621678 | H26: {=+H22:BO22+H24:BO24} -> 196939.86 | I26: 245592.75 | J26: 336842.02 | K26: 394600.97 | L26: 450328.23 | M26: 420417.39 | N26: 379399.76 | O26: 454462.77 | P26: 529954.93 | Q26: 635127.3 | R26: 799225.93 | S26: 662601.18 | T26: 419557.42 | U26: 471393.41 | V26: 546953.99 | W26: 609267.12 | X26: 669426.44 | Y26: 638054.19 | Z26: 594987.44 | AA26: 676033.98 | AB26: 757422.29 | AC26: 871885.93 | AD26: 1050514.3 | AE26: 899059.23 | AF26: 623994.41 | AG26: 679044.82 | AH26: 777611.33 | AI26: 843896.81 | AJ26: 907954.55 | AK26: 875126.81 | AL26: 829886.86 | AM26: 915369.3 | AN26: 1001392.8 | AO26: 1122516.9 | AP26: 1311299.9 | AQ26: 1146515.9 | AR26: 840026.29 | AS26: 897368.18 | AT26: 1014096.3 | AU26: 1083150.8 | AV26: 1149937.4 | AW26: 1116189.6 | AX26: 1069548.2 | AY26: 1158027.1 | AZ26: 1247201.8 | BA26: 1372756.2 | BB26: 1568207.4 | BC26: 1396972.1 | BD26: 1076974.1 | BE26: 1136289.5 | BF26: 1264067.3 | BG26: 1335623.5 | BH26: 1404865.2 | BI26: 1370281 | BJ26: 1321364.5 | BK26: 1413700.5 | BL26: 1505775 | BM26: 1635591.1 | BN26: 1837524.4 | BO26: 1661481
B28: Schedules and Supporting Calculations
B29: 1 Time Schedules
C31: Inflation Index | D31: 0.03 | F31: [coef] | H31: {=(1+Assumptions!D10)^(H10:BO10-$H$10)} -> 1 | I31: 1 | J31: 1 | K31: 1 | L31: 1 | M31: 1 | N31: 1 | O31: 1 | P31: 1 | Q31: 1 | R31: 1 | S31: 1 | T31: 1.03 | U31: 1.03 | V31: 1.03 | W31: 1.03 | X31: 1.03 | Y31: 1.03 | Z31: 1.03 | AA31: 1.03 | AB31: 1.03 | AC31: 1.03 | AD31: 1.03 | AE31: 1.03 | AF31: 1.0609 | AG31: 1.0609 | AH31: 1.0609 | AI31: 1.0609 | AJ31: 1.0609 | AK31: 1.0609 | AL31: 1.0609 | AM31: 1.0609 | AN31: 1.0609 | AO31: 1.0609 | AP31: 1.0609 | AQ31: 1.0609 | AR31: 1.092727 | AS31: 1.092727 | AT31: 1.092727 | AU31: 1.092727 | AV31: 1.092727 | AW31: 1.092727 | AX31: 1.092727 | AY31: 1.092727 | AZ31: 1.092727 | BA31: 1.092727 | BB31: 1.092727 | BC31: 1.092727 | BD31: 1.1255088 | BE31: 1.1255088 | BF31: 1.1255088 | BG31: 1.1255088 | BH31: 1.1255088 | BI31: 1.1255088 | BJ31: 1.1255088 | BK31: 1.1255088 | BL31: 1.1255088 | BM31: 1.1255088 | BN31: 1.1255088 | BO31: 1.1255088
B34: Customer Active Status | D34: =Assumptions!I24 -> Contract Active | E34: =Assumptions!D24 -> Starting Month
C35: {=cust} -> Michael’s Market Goods | D35: {=active} -> 1 | E35: {=month} -> 1 | F35: [flg] | G35: {=IF(_xlfn.ANCHORARRAY(D35)=1,IF(_xlfn.ANCHORARRAY(G7)>=_xlfn.ANCHORARRAY(E35),1,0),0)} -> 0 | H35: 1 | I35: 1 | J35: 1 | K35: 1 | L35: 1 | M35: 1 | N35: 1 | O35: 1 | P35: 1 | Q35: 1 | R35: 1 | S35: 1 | T35: 1 | U35: 1 | V35: 1 | W35: 1 | X35: 1 | Y35: 1 | Z35: 1 | AA35: 1 | AB35: 1 | AC35: 1 | AD35: 1 | AE35: 1 | AF35: 1 | AG35: 1 | AH35: 1 | AI35: 1 | AJ35: 1 | AK35: 1 | AL35: 1 | AM35: 1 | AN35: 1 | AO35: 1 | AP35: 1 | AQ35: 1 | AR35: 1 | AS35: 1 | AT35: 1 | AU35: 1 | AV35: 1 | AW35: 1 | AX35: 1 | AY35: 1 | AZ35: 1 | BA35: 1 | BB35: 1 | BC35: 1 | BD35: 1 | BE35: 1 | BF35: 1 | BG35: 1 | BH35: 1 | BI35: 1 | BJ35: 1 | BK35: 1 | BL35: 1 | BM35: 1 | BN35: 1 | BO35: 1 | BP35: 1
C36: Andrew Digital Commerce | D36: 1 | E36: 1 | F36: [flg] | G36: 0 | H36: 1 | I36: 1 | J36: 1 | K36: 1 | L36: 1 | M36: 1 | N36: 1 | O36: 1 | P36: 1 | Q36: 1 | R36: 1 | S36: 1 | T36: 1 | U36: 1 | V36: 1 | W36: 1 | X36: 1 | Y36: 1 | Z36: 1 | AA36: 1 | AB36: 1 | AC36: 1 | AD36: 1 | AE36: 1 | AF36: 1 | AG36: 1 | AH36: 1 | AI36: 1 | AJ36: 1 | AK36: 1 | AL36: 1 | AM36: 1 | AN36: 1 | AO36: 1 | AP36: 1 | AQ36: 1 | AR36: 1 | AS36: 1 | AT36: 1 | AU36: 1 | AV36: 1 | AW36: 1 | AX36: 1 | AY36: 1 | AZ36: 1 | BA36: 1 | BB36: 1 | BC36: 1 | BD36: 1 | BE36: 1 | BF36: 1 | BG36: 1 | BH36: 1 | BI36: 1 | BJ36: 1 | BK36: 1 | BL36: 1 | BM36: 1 | BN36: 1 | BO36: 1 | BP36: 1
C37: Anup Industrial Systems | D37: 1 | E37: 1 | F37: [flg] | G37: 0 | H37: 1 | I37: 1 | J37: 1 | K37: 1 | L37: 1 | M37: 1 | N37: 1 | O37: 1 | P37: 1 | Q37: 1 | R37: 1 | S37: 1 | T37: 1 | U37: 1 | V37: 1 | W37: 1 | X37: 1 | Y37: 1 | Z37: 1 | AA37: 1 | AB37: 1 | AC37: 1 | AD37: 1 | AE37: 1 | AF37: 1 | AG37: 1 | AH37: 1 | AI37: 1 | AJ37: 1 | AK37: 1 | AL37: 1 | AM37: 1 | AN37: 1 | AO37: 1 | AP37: 1 | AQ37: 1 | AR37: 1 | AS37: 1 | AT37: 1 | AU37: 1 | AV37: 1 | AW37: 1 | AX37: 1 | AY37: 1 | AZ37: 1 | BA37: 1 | BB37: 1 | BC37: 1 | BD37: 1 | BE37: 1 | BF37: 1 | BG37: 1 | BH37: 1 | BI37: 1 | BJ37: 1 | BK37: 1 | BL37: 1 | BM37: 1 | BN37: 1 | BO37: 1 | BP37: 1
C38: Joseph Retail Group | D38: 1 | E38: 1 | F38: [flg] | G38: 0 | H38: 1 | I38: 1 | J38: 1 | K38: 1 | L38: 1 | M38: 1 | N38: 1 | O38: 1 | P38: 1 | Q38: 1 | R38: 1 | S38: 1 | T38: 1 | U38: 1 | V38: 1 | W38: 1 | X38: 1 | Y38: 1 | Z38: 1 | AA38: 1 | AB38: 1 | AC38: 1 | AD38: 1 | AE38: 1 | AF38: 1 | AG38: 1 | AH38: 1 | AI38: 1 | AJ38: 1 | AK38: 1 | AL38: 1 | AM38: 1 | AN38: 1 | AO38: 1 | AP38: 1 | AQ38: 1 | AR38: 1 | AS38: 1 | AT38: 1 | AU38: 1 | AV38: 1 | AW38: 1 | AX38: 1 | AY38: 1 | AZ38: 1 | BA38: 1 | BB38: 1 | BC38: 1 | BD38: 1 | BE38: 1 | BF38: 1 | BG38: 1 | BH38: 1 | BI38: 1 | BJ38: 1 | BK38: 1 | BL38: 1 | BM38: 1 | BN38: 1 | BO38: 1 | BP38: 1
C39: Dim Collective | D39: 1 | E39: 1 | F39: [flg] | G39: 0 | H39: 1 | I39: 1 | J39: 1 | K39: 1 | L39: 1 | M39: 1 | N39: 1 | O39: 1 | P39: 1 | Q39: 1 | R39: 1 | S39: 1 | T39: 1 | U39: 1 | V39: 1 | W39: 1 | X39: 1 | Y39: 1 | Z39: 1 | AA39: 1 | AB39: 1 | AC39: 1 | AD39: 1 | AE39: 1 | AF39: 1 | AG39: 1 | AH39: 1 | AI39: 1 | AJ39: 1 | AK39: 1 | AL39: 1 | AM39: 1 | AN39: 1 | AO39: 1 | AP39: 1 | AQ39: 1 | AR39: 1 | AS39: 1 | AT39: 1 | AU39: 1 | AV39: 1 | AW39: 1 | AX39: 1 | AY39: 1 | AZ39: 1 | BA39: 1 | BB39: 1 | BC39: 1 | BD39: 1 | BE39: 1 | BF39: 1 | BG39: 1 | BH39: 1 | BI39: 1 | BJ39: 1 | BK39: 1 | BL39: 1 | BM39: 1 | BN39: 1 | BO39: 1 | BP39: 1
C40: Tim Forward Brands | D40: 0 | E40: 37 | F40: [flg] | G40: 0 | H40: 0 | I40: 0 | J40: 0 | K40: 0 | L40: 0 | M40: 0 | N40: 0 | O40: 0 | P40: 0 | Q40: 0 | R40: 0 | S40: 0 | T40: 0 | U40: 0 | V40: 0 | W40: 0 | X40: 0 | Y40: 0 | Z40: 0 | AA40: 0 | AB40: 0 | AC40: 0 | AD40: 0 | AE40: 0 | AF40: 0 | AG40: 0 | AH40: 0 | AI40: 0 | AJ40: 0 | AK40: 0 | AL40: 0 | AM40: 0 | AN40: 0 | AO40: 0 | AP40: 0 | AQ40: 0 | AR40: 0 | AS40: 0 | AT40: 0 | AU40: 0 | AV40: 0 | AW40: 0 | AX40: 0 | AY40: 0 | AZ40: 0 | BA40: 0 | BB40: 0 | BC40: 0 | BD40: 0 | BE40: 0 | BF40: 0 | BG40: 0 | BH40: 0 | BI40: 0 | BJ40: 0 | BK40: 0 | BL40: 0 | BM40: 0 | BN40: 0 | BO40: 0 | BP40: 0
B42: 2 Demand / Growth
B44: Seasonal Demand | D44: =Assumptions!C24 -> Segment
C45: {=cust} -> Michael’s Market Goods | D45: {=seg} -> Retail | F45: [%] | H45: {=INDEX(Assumptions!$D$47:$F$58,Model!H9:BP9,_xlfn.XMATCH(_xlfn.ANCHORARRAY(D45),Assumptions!D46:F46))} -> 0.75 | I45: 0.8 | J45: 0.85 | K45: 0.95 | L45: 1.1 | M45: 1.2 | N45: 0.9 | O45: 0.85 | P45: 1 | Q45: 1.05 | R45: 1.2 | S45: 1.35 | T45: 0.75 | U45: 0.8 | V45: 0.85 | W45: 0.95 | X45: 1.1 | Y45: 1.2 | Z45: 0.9 | AA45: 0.85 | AB45: 1 | AC45: 1.05 | AD45: 1.2 | AE45: 1.35 | AF45: 0.75 | AG45: 0.8 | AH45: 0.85 | AI45: 0.95 | AJ45: 1.1 | AK45: 1.2 | AL45: 0.9 | AM45: 0.85 | AN45: 1 | AO45: 1.05 | AP45: 1.2 | AQ45: 1.35 | AR45: 0.75 | AS45: 0.8 | AT45: 0.85 | AU45: 0.95 | AV45: 1.1 | AW45: 1.2 | AX45: 0.9 | AY45: 0.85 | AZ45: 1 | BA45: 1.05 | BB45: 1.2 | BC45: 1.35 | BD45: 0.75 | BE45: 0.8 | BF45: 0.85 | BG45: 0.95 | BH45: 1.1 | BI45: 1.2 | BJ45: 0.9 | BK45: 0.85 | BL45: 1 | BM45: 1.05 | BN45: 1.2 | BO45: 1.35 | BP45: 0.75
C46: Andrew Digital Commerce | D46: E-commerce | F46: [%] | H46: 0.75 | I46: 0.65 | J46: 0.7 | K46: 0.75 | L46: 0.7 | M46: 0.75 | N46: 0.7 | O46: 0.9 | P46: 1.05 | Q46: 1.1 | R46: 1.75 | S46: 2.2 | T46: 0.75 | U46: 0.65 | V46: 0.7 | W46: 0.75 | X46: 0.7 | Y46: 0.75 | Z46: 0.7 | AA46: 0.9 | AB46: 1.05 | AC46: 1.1 | AD46: 1.75 | AE46: 2.2 | AF46: 0.75 | AG46: 0.65 | AH46: 0.7 | AI46: 0.75 | AJ46: 0.7 | AK46: 0.75 | AL46: 0.7 | AM46: 0.9 | AN46: 1.05 | AO46: 1.1 | AP46: 1.75 | AQ46: 2.2 | AR46: 0.75 | AS46: 0.65 | AT46: 0.7 | AU46: 0.75 | AV46: 0.7 | AW46: 0.75 | AX46: 0.7 | AY46: 0.9 | AZ46: 1.05 | BA46: 1.1 | BB46: 1.75 | BC46: 2.2 | BD46: 0.75 | BE46: 0.65 | BF46: 0.7 | BG46: 0.75 | BH46: 0.7 | BI46: 0.75 | BJ46: 0.7 | BK46: 0.9 | BL46: 1.05 | BM46: 1.1 | BN46: 1.75 | BO46: 2.2 | BP46: 0.75
C47: Anup Industrial Systems | D47: Industrial | F47: [%] | H47: 0.95 | I47: 0.95 | J47: 1 | K47: 1 | L47: 1 | M47: 1 | N47: 0.95 | O47: 0.9 | P47: 1.1 | Q47: 1.1 | R47: 1.05 | S47: 1 | T47: 0.95 | U47: 0.95 | V47: 1 | W47: 1 | X47: 1 | Y47: 1 | Z47: 0.95 | AA47: 0.9 | AB47: 1.1 | AC47: 1.1 | AD47: 1.05 | AE47: 1 | AF47: 0.95 | AG47: 0.95 | AH47: 1 | AI47: 1 | AJ47: 1 | AK47: 1 | AL47: 0.95 | AM47: 0.9 | AN47: 1.1 | AO47: 1.1 | AP47: 1.05 | AQ47: 1 | AR47: 0.95 | AS47: 0.95 | AT47: 1 | AU47: 1 | AV47: 1 | AW47: 1 | AX47: 0.95 | AY47: 0.9 | AZ47: 1.1 | BA47: 1.1 | BB47: 1.05 | BC47: 1 | BD47: 0.95 | BE47: 0.95 | BF47: 1 | BG47: 1 | BH47: 1 | BI47: 1 | BJ47: 0.95 | BK47: 0.9 | BL47: 1.1 | BM47: 1.1 | BN47: 1.05 | BO47: 1 | BP47: 0.95
C48: Joseph Retail Group | D48: Retail | F48: [%] | H48: 0.75 | I48: 0.8 | J48: 0.85 | K48: 0.95 | L48: 1.1 | M48: 1.2 | N48: 0.9 | O48: 0.85 | P48: 1 | Q48: 1.05 | R48: 1.2 | S48: 1.35 | T48: 0.75 | U48: 0.8 | V48: 0.85 | W48: 0.95 | X48: 1.1 | Y48: 1.2 | Z48: 0.9 | AA48: 0.85 | AB48: 1 | AC48: 1.05 | AD48: 1.2 | AE48: 1.35 | AF48: 0.75 | AG48: 0.8 | AH48: 0.85 | AI48: 0.95 | AJ48: 1.1 | AK48: 1.2 | AL48: 0.9 | AM48: 0.85 | AN48: 1 | AO48: 1.05 | AP48: 1.2 | AQ48: 1.35 | AR48: 0.75 | AS48: 0.8 | AT48: 0.85 | AU48: 0.95 | AV48: 1.1 | AW48: 1.2 | AX48: 0.9 | AY48: 0.85 | AZ48: 1 | BA48: 1.05 | BB48: 1.2 | BC48: 1.35 | BD48: 0.75 | BE48: 0.8 | BF48: 0.85 | BG48: 0.95 | BH48: 1.1 | BI48: 1.2 | BJ48: 0.9 | BK48: 0.85 | BL48: 1 | BM48: 1.05 | BN48: 1.2 | BO48: 1.35 | BP48: 0.75
C49: Dim Collective | D49: Retail | F49: [%] | H49: 0.75 | I49: 0.8 | J49: 0.85 | K49: 0.95 | L49: 1.1 | M49: 1.2 | N49: 0.9 | O49: 0.85 | P49: 1 | Q49: 1.05 | R49: 1.2 | S49: 1.35 | T49: 0.75 | U49: 0.8 | V49: 0.85 | W49: 0.95 | X49: 1.1 | Y49: 1.2 | Z49: 0.9 | AA49: 0.85 | AB49: 1 | AC49: 1.05 | AD49: 1.2 | AE49: 1.35 | AF49: 0.75 | AG49: 0.8 | AH49: 0.85 | AI49: 0.95 | AJ49: 1.1 | AK49: 1.2 | AL49: 0.9 | AM49: 0.85 | AN49: 1 | AO49: 1.05 | AP49: 1.2 | AQ49: 1.35 | AR49: 0.75 | AS49: 0.8 | AT49: 0.85 | AU49: 0.95 | AV49: 1.1 | AW49: 1.2 | AX49: 0.9 | AY49: 0.85 | AZ49: 1 | BA49: 1.05 | BB49: 1.2 | BC49: 1.35 | BD49: 0.75 | BE49: 0.8 | BF49: 0.85 | BG49: 0.95 | BH49: 1.1 | BI49: 1.2 | BJ49: 0.9 | BK49: 0.85 | BL49: 1 | BM49: 1.05 | BN49: 1.2 | BO49: 1.35 | BP49: 0.75
C50: Tim Forward Brands | D50: Retail | F50: [%] | H50: 0.75 | I50: 0.8 | J50: 0.85 | K50: 0.95 | L50: 1.1 | M50: 1.2 | N50: 0.9 | O50: 0.85 | P50: 1 | Q50: 1.05 | R50: 1.2 | S50: 1.35 | T50: 0.75 | U50: 0.8 | V50: 0.85 | W50: 0.95 | X50: 1.1 | Y50: 1.2 | Z50: 0.9 | AA50: 0.85 | AB50: 1 | AC50: 1.05 | AD50: 1.2 | AE50: 1.35 | AF50: 0.75 | AG50: 0.8 | AH50: 0.85 | AI50: 0.95 | AJ50: 1.1 | AK50: 1.2 | AL50: 0.9 | AM50: 0.85 | AN50: 1 | AO50: 1.05 | AP50: 1.2 | AQ50: 1.35 | AR50: 0.75 | AS50: 0.8 | AT50: 0.85 | AU50: 0.95 | AV50: 1.1 | AW50: 1.2 | AX50: 0.9 | AY50: 0.85 | AZ50: 1 | BA50: 1.05 | BB50: 1.2 | BC50: 1.35 | BD50: 0.75 | BE50: 0.8 | BF50: 0.85 | BG50: 0.95 | BH50: 1.1 | BI50: 1.2 | BJ50: 0.9 | BK50: 0.85 | BL50: 1 | BM50: 1.05 | BN50: 1.2 | BO50: 1.35 | BP50: 0.75
B52: Customer YoY Growth
C53: {=cust} -> Michael’s Market Goods | F53: [%] | H53: {=INDEX(Assumptions!D36:H41,_xlfn.XMATCH(_xlfn.ANCHORARRAY(Model!C53),Assumptions!B36:B41),_xlfn.XMATCH(Model!H10:BP10-Model!G10,Assumptions!D35:H35,-1))} -> 0.07 | I53: 0.07 | J53: 0.07 | K53: 0.07 | L53: 0.07 | M53: 0.07 | N53: 0.07 | O53: 0.07 | P53: 0.07 | Q53: 0.07 | R53: 0.07 | S53: 0.07 | T53: 0.05 | U53: 0.05 | V53: 0.05 | W53: 0.05 | X53: 0.05 | Y53: 0.05 | Z53: 0.05 | AA53: 0.05 | AB53: 0.05 | AC53: 0.05 | AD53: 0.05 | AE53: 0.05 | AF53: 0.05 | AG53: 0.05 | AH53: 0.05 | AI53: 0.05 | AJ53: 0.05 | AK53: 0.05 | AL53: 0.05 | AM53: 0.05 | AN53: 0.05 | AO53: 0.05 | AP53: 0.05 | AQ53: 0.05 | AR53: 0.03 | AS53: 0.03 | AT53: 0.03 | AU53: 0.03 | AV53: 0.03 | AW53: 0.03 | AX53: 0.03 | AY53: 0.03 | AZ53: 0.03 | BA53: 0.03 | BB53: 0.03 | BC53: 0.03 | BD53: 0.02 | BE53: 0.02 | BF53: 0.02 | BG53: 0.02 | BH53: 0.02 | BI53: 0.02 | BJ53: 0.02 | BK53: 0.02 | BL53: 0.02 | BM53: 0.02 | BN53: 0.02 | BO53: 0.02 | BP53: 0.02
C54: Andrew Digital Commerce | F54: [%] | H54: 0.12 | I54: 0.12 | J54: 0.12 | K54: 0.12 | L54: 0.12 | M54: 0.12 | N54: 0.12 | O54: 0.12 | P54: 0.12 | Q54: 0.12 | R54: 0.12 | S54: 0.12 | T54: 0.06 | U54: 0.06 | V54: 0.06 | W54: 0.06 | X54: 0.06 | Y54: 0.06 | Z54: 0.06 | AA54: 0.06 | AB54: 0.06 | AC54: 0.06 | AD54: 0.06 | AE54: 0.06 | AF54: 0.02 | AG54: 0.02 | AH54: 0.02 | AI54: 0.02 | AJ54: 0.02 | AK54: 0.02 | AL54: 0.02 | AM54: 0.02 | AN54: 0.02 | AO54: 0.02 | AP54: 0.02 | AQ54: 0.02 | AR54: 0 | AS54: 0 | AT54: 0 | AU54: 0 | AV54: 0 | AW54: 0 | AX54: 0 | AY54: 0 | AZ54: 0 | BA54: 0 | BB54: 0 | BC54: 0 | BD54: 0 | BE54: 0 | BF54: 0 | BG54: 0 | BH54: 0 | BI54: 0 | BJ54: 0 | BK54: 0 | BL54: 0 | BM54: 0 | BN54: 0 | BO54: 0 | BP54: 0
C55: Anup Industrial Systems | F55: [%] | H55: 0.01 | I55: 0.01 | J55: 0.01 | K55: 0.01 | L55: 0.01 | M55: 0.01 | N55: 0.01 | O55: 0.01 | P55: 0.01 | Q55: 0.01 | R55: 0.01 | S55: 0.01 | T55: 0.005 | U55: 0.005 | V55: 0.005 | W55: 0.005 | X55: 0.005 | Y55: 0.005 | Z55: 0.005 | AA55: 0.005 | AB55: 0.005 | AC55: 0.005 | AD55: 0.005 | AE55: 0.005 | AF55: 0 | AG55: 0 | AH55: 0 | AI55: 0 | AJ55: 0 | AK55: 0 | AL55: 0 | AM55: 0 | AN55: 0 | AO55: 0 | AP55: 0 | AQ55: 0 | AR55: -0.01 | AS55: -0.01 | AT55: -0.01 | AU55: -0.01 | AV55: -0.01 | AW55: -0.01 | AX55: -0.01 | AY55: -0.01 | AZ55: -0.01 | BA55: -0.01 | BB55: -0.01 | BC55: -0.01 | BD55: -0.015 | BE55: -0.015 | BF55: -0.015 | BG55: -0.015 | BH55: -0.015 | BI55: -0.015 | BJ55: -0.015 | BK55: -0.015 | BL55: -0.015 | BM55: -0.015 | BN55: -0.015 | BO55: -0.015 | BP55: -0.015
C56: Joseph Retail Group | F56: [%] | H56: -0.08 | I56: -0.08 | J56: -0.08 | K56: -0.08 | L56: -0.08 | M56: -0.08 | N56: -0.08 | O56: -0.08 | P56: -0.08 | Q56: -0.08 | R56: -0.08 | S56: -0.08 | T56: -0.04 | U56: -0.04 | V56: -0.04 | W56: -0.04 | X56: -0.04 | Y56: -0.04 | Z56: -0.04 | AA56: -0.04 | AB56: -0.04 | AC56: -0.04 | AD56: -0.04 | AE56: -0.04 | AF56: -0.06 | AG56: -0.06 | AH56: -0.06 | AI56: -0.06 | AJ56: -0.06 | AK56: -0.06 | AL56: -0.06 | AM56: -0.06 | AN56: -0.06 | AO56: -0.06 | AP56: -0.06 | AQ56: -0.06 | AR56: -0.08 | AS56: -0.08 | AT56: -0.08 | AU56: -0.08 | AV56: -0.08 | AW56: -0.08 | AX56: -0.08 | AY56: -0.08 | AZ56: -0.08 | BA56: -0.08 | BB56: -0.08 | BC56: -0.08 | BD56: -0.07 | BE56: -0.07 | BF56: -0.07 | BG56: -0.07 | BH56: -0.07 | BI56: -0.07 | BJ56: -0.07 | BK56: -0.07 | BL56: -0.07 | BM56: -0.07 | BN56: -0.07 | BO56: -0.07 | BP56: -0.07
C57: Dim Collective | F57: [%] | H57: 0.3 | I57: 0.3 | J57: 0.3 | K57: 0.3 | L57: 0.3 | M57: 0.3 | N57: 0.3 | O57: 0.3 | P57: 0.3 | Q57: 0.3 | R57: 0.3 | S57: 0.3 | T57: 0.15 | U57: 0.15 | V57: 0.15 | W57: 0.15 | X57: 0.15 | Y57: 0.15 | Z57: 0.15 | AA57: 0.15 | AB57: 0.15 | AC57: 0.15 | AD57: 0.15 | AE57: 0.15 | AF57: 0.1 | AG57: 0.1 | AH57: 0.1 | AI57: 0.1 | AJ57: 0.1 | AK57: 0.1 | AL57: 0.1 | AM57: 0.1 | AN57: 0.1 | AO57: 0.1 | AP57: 0.1 | AQ57: 0.1 | AR57: 0.06 | AS57: 0.06 | AT57: 0.06 | AU57: 0.06 | AV57: 0.06 | AW57: 0.06 | AX57: 0.06 | AY57: 0.06 | AZ57: 0.06 | BA57: 0.06 | BB57: 0.06 | BC57: 0.06 | BD57: 0.04 | BE57: 0.04 | BF57: 0.04 | BG57: 0.04 | BH57: 0.04 | BI57: 0.04 | BJ57: 0.04 | BK57: 0.04 | BL57: 0.04 | BM57: 0.04 | BN57: 0.04 | BO57: 0.04 | BP57: 0.04
C58: Tim Forward Brands | F58: [%] | H58: 0 | I58: 0 | J58: 0 | K58: 0 | L58: 0 | M58: 0 | N58: 0 | O58: 0 | P58: 0 | Q58: 0 | R58: 0 | S58: 0 | T58: 0 | U58: 0 | V58: 0 | W58: 0 | X58: 0 | Y58: 0 | Z58: 0 | AA58: 0 | AB58: 0 | AC58: 0 | AD58: 0 | AE58: 0 | AF58: 0 | AG58: 0 | AH58: 0 | AI58: 0 | AJ58: 0 | AK58: 0 | AL58: 0 | AM58: 0 | AN58: 0 | AO58: 0 | AP58: 0 | AQ58: 0 | AR58: 0.1448 | AS58: 0.1448 | AT58: 0.1448 | AU58: 0.1448 | AV58: 0.1448 | AW58: 0.1448 | AX58: 0.1448 | AY58: 0.1448 | AZ58: 0.1448 | BA58: 0.1448 | BB58: 0.1448 | BC58: 0.1448 | BD58: 0.04 | BE58: 0.04 | BF58: 0.04 | BG58: 0.04 | BH58: 0.04 | BI58: 0.04 | BJ58: 0.04 | BK58: 0.04 | BL58: 0.04 | BM58: 0.04 | BN58: 0.04 | BO58: 0.04 | BP58: 0.04
B60: 3 Volumes
B62: Base Annual Parcels
C63: {=cust} -> Michael’s Market Goods | D63: {=starting_parc} -> 375000 | E63: ="Starting " & Assumptions!E24 -> Starting Monthly Outbound Parcels | F63: [parcel] | G63: {=starting_parc} -> 375000 | H63: {=INDEX(Assumptions!$K$36:$P$41,_xlfn.XMATCH(_xlfn.ANCHORARRAY(Model!C63),Assumptions!$B$36:$B$41),$H$10:$BP$10-$G$10)*H35:BP40} -> 401250 | I63: 401250 | J63: 401250 | K63: 401250 | L63: 401250 | M63: 401250 | N63: 401250 | O63: 401250 | P63: 401250 | Q63: 401250 | R63: 401250 | S63: 401250 | T63: 421312.5 | U63: 421312.5 | V63: 421312.5 | W63: 421312.5 | X63: 421312.5 | Y63: 421312.5 | Z63: 421312.5 | AA63: 421312.5 | AB63: 421312.5 | AC63: 421312.5 | AD63: 421312.5 | AE63: 421312.5 | AF63: 442378.12 | AG63: 442378.12 | AH63: 442378.12 | AI63: 442378.12 | AJ63: 442378.12 | AK63: 442378.12 | AL63: 442378.12 | AM63: 442378.12 | AN63: 442378.12 | AO63: 442378.12 | AP63: 442378.12 | AQ63: 442378.12 | AR63: 455649.47 | AS63: 455649.47 | AT63: 455649.47 | AU63: 455649.47 | AV63: 455649.47 | AW63: 455649.47 | AX63: 455649.47 | AY63: 455649.47 | AZ63: 455649.47 | BA63: 455649.47 | BB63: 455649.47 | BC63: 455649.47 | BD63: 464762.46 | BE63: 464762.46 | BF63: 464762.46 | BG63: 464762.46 | BH63: 464762.46 | BI63: 464762.46 | BJ63: 464762.46 | BK63: 464762.46 | BL63: 464762.46 | BM63: 464762.46 | BN63: 464762.46 | BO63: 464762.46 | BP63: 474057.71
...

Sheet Model Validation
C2: Questions & Answers
B4: # | C4: Question | D4: Points | E4: Section | F4: Answer | G4: Correct Answer
B6: Part 1 - Without the New Client
B7: 1 | C7: What are the Anup Industrial Systems Outbound Parcels in 03/2026? | D7: 20 | E7: =--(F7=G7) -> 1 | F7: =Model!J65 -> 227250 | G7: 227250
B8: 2 | C8: What are the Michael’s Market Goods Outbound Pallets in year 2027? | D8: 20 | E8: =--(F8=G8) -> 1 | F8: =SUM(Model!T80:AE80) -> 280875 | G8: 280875
B9: 3 | C9: What are the Andrew Digital Commerce Inbound Pallets in 11/2027? | D9: 25 | E9: =--(F9=G9) -> 1 | F9: =ROUND(Model!AD90,0) -> 41528 | G9: 41528
B10: 4 | C10: What is the monthly peak total revenue from pallets storage of 2026? | D10: 25 | E10: =--(F10=G10) -> 0 | G10: 517244
B11: 5 | C11: What is the total revenue from inbound handling over the 5-year period? | D11: 25 | E11: =--(F11=G11) -> 1 | F11: =ROUND(SUM(Model!H127:BO127),0) -> 22681102 | G11: 22681102
B12: 6 | C12: How many FTE will be needed to handle the Replenishment in 01/2026? | D12: 25 | E12: =--(F12=G12) -> 1 | F12: =ROUND(Model!H222,2) -> 24.16 | G12: 24.16
B13: 7 | C13: How many temporary staff will be needed in 11/2026? | D13: 25 | E13: =--(F13=G13) -> 1 | F13: =ROUND(Model!R234,0) -> 110 | G13: 110
B14: 8 | C14: Assuming you had 1 more permanent staff in 2026, how much money would you save during the year by not using a temporary worker? | D14: 25 | E14: =--(F14=G14) -> 1 | F14: =ROUND(SUM(Model!H250:S250),0) -> 1280 | G14: 1280
B15: 9 | C15: How many additional permanent staff will be hired at the beginning of 2027? | D15: 25 | E15: =--(F15=G15) -> 1 | F15: =Model!T229 -> 2 | G15: 2
B16: 10 | C16: What is the total cost of temporary staff over the 5-year period? | D16: 25 | E16: =--(F16=G16) -> 1 | F16: =ROUND(SUM(Model!H244:BO244),0) -> 11150061 | G16: 11150061
B17: 11 | C17: How many Reach Trucks will be needed to handle the Replenishment in 01/2026? | D17: 20 | E17: =--(F17=G17) -> 1 | F17: 8.05 | G17: 8.05
B18: 12 | C18: How many Power Pallet Trucks will be needed for all activities in 02/2026? | D18: 20 | E18: =--(F18=G18) -> 1 | F18: =Model!I309 -> 34 | G18: 34
B19: 13 | C19: Which month will you buy the first additional Reach Truck? | D19: 25 | E19: =--(F19=G19) -> 1 | F19: 46143 | G19: 46143
B20: 14 | C20: What is the total amount invested into the trucks over the 5-year period? | D20: 25 | E20: =--(F20=G20) -> 1 | F20: =ROUND(SUM(_xlfn.ANCHORARRAY(Model!H326)),0) -> 1254790 | G20: 1254790
B21: 15 | C21: How many hours Powered Pallet Trucks will be used in 03/2026 for Inbound Unloading Activity? | D21: 25 | E21: =--(F21=G21) -> 1 | F21: =ROUND(Model!J285,0) -> 4834 | G21: 4834
B22: 16 | C22: What is the total cost of energy consumption by all trucks for 01/2027? | D22: 25 | E22: =--(F22=G22) -> 1 | F22: =ROUND(Model!T341,0) -> 19003 | G22: 19003
B23: 17 | C23: What is the amount of fixed COGS incurred in 01/2027? | D23: 20 | E23: =--(F23=G23) -> 1 | F23: =Model!T350 -> 61800 | G23: 61800
B24: 18 | C24: What is the total amount of SG&A costs incurred over the 5-year period? | D24: 20 | E24: =--(F24=G24) -> 1 | F24: =-ROUND(SUM(_xlfn.ANCHORARRAY(Model!H24)),0) -> 3981852 | G24: 3981852
B25: 19 | C25: What is the total EBITDA for the 5-year period? | D25: 50 | E25: =--(F25=G25) -> 0 | F25: =ROUND(Model!E17,0) -> 0 | G25: 55621678
B27: Part 2 - With the New Client
B28: 20 | C28: If Tim Forward Brands sign the contract, what is the total EBITDA for the 5-year period? | D28: 30 | E28: =--(F28=G28) -> 0 | F28: =ROUND(Model!E16,0) -> 0 | G28: 61161159
D30: 500

Sheet _avcts_version_hash
A1: i1OwNHgEFD7u0auo+Co71V9hKviRajTQWEUZo+yMHv8KRTVltoK89vUtgaZa9WvkoPPvK5pehJezplZYqVf4UNSJFDbCFFOUkz2Iv3abUXo6IhuNv1jmsp7DvEhQbpVogQKJGURxAFAwXfKVo53wJFASqhGt8cuKwG4jZZ69d+FjgTe78eBYzTIUgU9a4da1xilS
